Workbook

Sheet Read me
A1: Monitoring and Evaluation System: data dictionary (Level 3)
A2: Draft v0.1 · 27 Sep 2026 · for review by the MoC M&E Secretariat. Nothing has been created in a database yet.
A4: What this is
A5: Every table and field the platform's database will hold, with a real example from the National Cashew Policy workspace. Table names match the Level 2 diagram in Figma.
A7: How to review
A8: 1. Read the 'Tables' sheet for the overall picture (29 tables in 8 families).
A9: 2. On the 'Fields' sheet, filter by Family or Table. Write comments in the yellow 'Reviewer comment' column (the only column to edit).
A10: 3. Check 'Allowed values' and 'Rules' for workflow and calculation rules.
A11: 4. Answer the 'Open questions' sheet (yellow cells).
A13: Column guide (Fields sheet)
A14: Key: PK = unique ID of the row · FK = link to another table (see References) · UK = must be unique (within the rule shown).
A15: Required: Y = must always have a value · N = may be empty. Empty means 'no data', never zero.
... A26: Platform specification v1.0 and engineering contracts (24 Sep 2026); Cashew Action-Level workbook v5, Outcome workbook v12, Kobo XLSForm v10, Monitoring System Manual v3, MTR final draft; owner decisions on roles (26 Sep 2026).

Sheet Tables
A1: # | B1: Family | C1: Table (database name) | D1: Diagram name | E1: Purpose | F1: Cashew example | G1: Pilot size (rows) | H1: Fields (own) | I1: Fields incl. common | J1: Reviewer comment
A2: 1 | B2: Structure | C2: workspaces | D2: new in Level 3 | E2: One isolated customer environment. Every other table belongs to exactly one workspace. | F2: Cashew Policy M&E (MoC) | G2: 1 | H2: =COUNTIF(Fields!$B$2:$B$400,C2) | I2: =H2+5
A3: 2 | B3: Structure | C3: policies | D3: POLICY | E3: A policy being monitored. | F3: NCP-2022 National Cashew Policy 2022–2027 | G3: 1 | H3: =COUNTIF(Fields!$B$2:$B$400,C3) | I3: =H3+6
A4: 3 | B4: Structure | C4: goals | D4: GOAL | E4: A goal (objective) of a policy. | F4: G2 Promote industrialisation: 25% processed by 2027 | G4: 3 | H4: =COUNTIF(Fields!$B$2:$B$400,C4) | I4: =H4+6
A5: 4 | B5: Structure | C5: clusters | D5: CLUSTER | E5: A group of actions delivering one goal. | F5: processing (actions 18–28) | G5: 3 | H5: =COUNTIF(Fields!$B$2:$B$400,C5) | I5: =H5+6
A6: 5 | B6: Structure | C6: ministries | D6: MINISTRY | E6: A ministry or institution that implements or reports. | F6: maff · MAFF | G6: 18 | H6: =COUNTIF(Fields!$B$2:$B$400,C6) | I6: =H6+6
A7: 6 | B7: Structure | C7: programmes | D7: PROGRAMME | E7: One programme per ministry under a policy; owns the actions that ministry leads. | F7: PRG-MAFF | G7: 17 | H7: =COUNTIF(Fields!$B$2:$B$400,C7) | I7: =H7+6
A8: 7 | B8: Structure | C8: actions | D8: ACTION | E8: A policy action (the platform's 'project'). | F8: ACT-02 Research on cashew varieties | G8: 44 | H8: =COUNTIF(Fields!$B$2:$B$400,C8) | I8: =H8+6
A9: 8 | B9: Structure | C9: action_ministries | D9: ACTION_MINISTRY | E9: Which ministries lead or contribute to an action. | F9: ACT-05 · moe · contributing | G9: ~60 | H9: =COUNTIF(Fields!$B$2:$B$400,C9) | I9: =H9+6
A10: 9 | B10: Indicators | C10: indicators | D10: INDICATOR | E10: Stable identity of an indicator (action or outcome level). | F10: AI-002 New cashew varieties released | G10: 121 | H10: =COUNTIF(Fields!$B$2:$B$400,C10) | I10: =H10+6
A11: 10 | B11: Indicators | C11: indicator_versions | D11: INDICATOR_VERSION | E11: The definition of an indicator at a point in time. A change of meaning creates a new version. | F11: AI-002 v1 · count to target · varieties | G11: 121+ | H11: =COUNTIF(Fields!$B$2:$B$400,C11) | I11: =H11+6
A12: 11 | B12: Indicators | C12: targets | D12: TARGET | E12: Target value for an indicator and year, with revision history. | F12: AI-002 · 2027 · 7 | G12: 108+ | H12: =COUNTIF(Fields!$B$2:$B$400,C12) | I12: =H12+6
A13: 12 | B13: Indicators | C13: baselines | D13: BASELINE | E13: Starting value for an indicator, or the reason it is unknown. | F13: P2 · 2022 · 508,283 t | G13: 13+ | H13: =COUNTIF(Fields!$B$2:$B$400,C13) | I13: =H13+6
A14: 13 | B14: Indicators | C14: reporting_years | D14: REPORTING_YEAR | E14: A reporting period with its deadline and status thresholds. | F14: 2026 · largely ≥ 70% · due 31 Mar 2027 | G14: 4 | H14: =COUNTIF(Fields!$B$2:$B$400,C14) | I14: =H14+6
... A21: 20 | B21: Collection | C21: evidence_files | D21: EVIDENCE | E21: Details of an uploaded evidence file. The file itself is in private file storage. | F21: variety-release-2025.pdf | G21: ~120 / year | H21: =COUNTIF(Fields!$B$2:$B$400,C21) | I21: =H21+6
A22: 21 | B22: Review | C22: review_events | D22: REVIEW_EVENT | E22: A decision or query on a submission revision. Never edited or deleted. | F22: RY2026-NBC r1 · returned | G22: ~50 / year | H22: =COUNTIF(Fields!$B$2:$B$400,C22) | I22: =H22+4
A23: 22 | B23: Review | C23: quality_flags | D23: QUALITY_FLAG | E23: An automatic or manual data-quality warning on a revision. | F23: AI-030 · no evidence file | G23: ~200 / year | H23: =COUNTIF(Fields!$B$2:$B$400,C23) | I23: =H23+6
A24: 23 | B24: Results | C24: results | D24: RESULT | E24: The official value of an indicator for a year, from an approved answer or an administrative source. | F24: AI-002 · 2025 · 4 · largely achieved | G24: ~121 / year | H24: =COUNTIF(Fields!$B$2:$B$400,C24) | I24: =H24+6
A25: 24 | B25: Reports | C25: reports | D25: REPORT | E25: A report identity (e.g. the annual report). | F25: AR-2025 Annual report | G25: 3 | H25: =COUNTIF(Fields!$B$2:$B$400,C25) | I25: =H25+6
A26: 25 | B26: Reports | C26: report_versions | D26: REPORT_VERSION | E26: A published, frozen snapshot of a report. | F26: AR-2025 v1 · 27 May 2026 | G26: 3+ | H26: =COUNTIF(Fields!$B$2:$B$400,C26) | I26: =H26+6
A27: 26 | B27: Users & access | C27: users | D27: APP_USER | E27: A person who can sign in. | F27: MAFF focal point | G27: ~30 | H27: =COUNTIF(Fields!$B$2:$B$400,C27) | I27: =H27+6
A28: 27 | B28: Users & access | C28: memberships | D28: MEMBERSHIP | E28: A user's membership of a workspace and ministry. | F28: user · maff | G28: ~30 | H28: =COUNTIF(Fields!$B$2:$B$400,C28) | I28: =H28+6
A29: 28 | B29: Users & access | C29: role_grants | D29: ROLE_GRANT | E29: A role given to a membership for a scope. | F29: focal · ministry maff | G29: ~35 | H29: =COUNTIF(Fields!$B$2:$B$400,C29) | I29: =H29+6
A30: 29 | B30: Control | C30: audit_events | D30: AUDIT_EVENT | E30: Permanent record of important actions. Insert-only. | F30: submission.approved · RY2026-MRD | G30: thousands | H30: =COUNTIF(Fields!$B$2:$B$400,C30) | I30: =H30+4
G31: Total | H31: =SUM(H2:H30) | I31: =SUM(I2:I30)
G32: Common fields per table: 6 (5 on workspaces; review_events and audit_events have no updated_at/row_version).

Sheet Fields
A1: Family | B1: Table | C1: Field | D1: Type | E1: Key | F1: Required | G1: References | H1: Rule / allowed values | I1: Description | J1: Cashew example | K1: Reviewer comment
A2: All tables | B2: (every table) | C2: id | D2: uuid | E2: PK | F2: Y | H2: Generated | I2: Unique identifier of the row. | J2: 8f3c…
A3: All tables | B3: (every table) | C3: workspace_id | D3: uuid | E3: FK | F3: Y | G3: workspaces.id | H3: Must match the parent row's workspace | I3: Which workspace the row belongs to. Not on workspaces itself. | J3: Cashew workspace
A4: All tables | B4: (every table) | C4: created_at | D4: timestamptz | F4: Y | H4: UTC, set by the database | I4: When the row was created. | J4: 2026-05-11 09:14 UTC
A5: All tables | B5: (every table) | C5: created_by | D5: uuid | E5: FK | F5: N | G5: users.id | H5: Empty for imported/system rows | I5: Who created the row. | J5: Secretariat lead
A6: All tables | B6: (every table) | C6: updated_at | D6: timestamptz | F6: Y | H6: UTC | I6: When the row last changed. Not on insert-only tables. | J6: 2026-05-12 10:00 UTC
A7: All tables | B7: (every table) | C7: row_version | D7: integer | F7: Y | H7: Starts at 1; +1 on every update | I7: Detects two people editing at once (stale edit is refused). | J7: 3
A8: Structure | B8: workspaces | C8: code | D8: text | E8: UK | F8: Y | H8: Unique, lowercase | I8: Short code. | J8: cashew-moc
A9: Structure | B9: workspaces | C9: name | D9: text | F9: Y | I9: Display name. | J9: Cashew Policy M&E (MoC)
A10: Structure | B10: workspaces | C10: timezone | D10: text | F10: Y | H10: IANA timezone | I10: Used for deadlines and period boundaries. | J10: Asia/Phnom_Penh
A11: Structure | B11: workspaces | C11: default_language | D11: text | F11: Y | H11: en | km | I11: Default language of labels. | J11: km
A12: Structure | B12: workspaces | C12: status | D12: text | F12: Y | H12: active | archived | J12: active
A13: Structure | B13: policies | C13: code | D13: text | E13: UK | F13: Y | H13: Unique in workspace | I13: Short code. | J13: NCP-2022
A14: Structure | B14: policies | C14: name_en | D14: text | F14: Y | I14: Name in English. | J14: National Cashew Policy 2022–2027
A15: Structure | B15: policies | C15: name_km | D15: text | F15: N | I15: Name in Khmer. | J15: គោលនយោបាយជាតិស្តីពីស្វាយចន្ទី…
A16: Structure | B16: policies | C16: vision | D16: text | F16: N | I16: Vision statement. | J16: Develop cashew production, processing and markets…
A17: Structure | B17: policies | C17: start_date | D17: date | F17: Y | I17: Policy start. | J17: 2022-01-01
A18: Structure | B18: policies | C18: end_date | D18: date | F18: Y | H18: ≥ start_date | I18: Policy end. | J18: 2027-12-31
A19: Structure | B19: policies | C19: approved_on | D19: date | F19: N | I19: Approval date. | J19: 2023-01-13
A20: Structure | B20: policies | C20: approved_by | D20: text | F20: N | I20: Approving body. | J20: Council of Ministers
A21: Structure | B21: policies | C21: owner_ministry_id | D21: uuid | E21: FK | F21: Y | G21: ministries.id | I21: Ministry accountable for the policy. | J21: moc
A22: Structure | B22: policies | C22: status | D22: text | F22: Y | H22: draft | active | closed | archived | J22: active
A23: Structure | B23: goals | C23: policy_id | D23: uuid | E23: FK | F23: Y | G23: policies.id | I23: Policy the goal belongs to. | J23: NCP-2022
A24: Structure | B24: goals | C24: code | D24: text | E24: UK | F24: Y | H24: Unique within the policy | I24: Short code. | J24: G2
A25: Structure | B25: goals | C25: text_en | D25: text | F25: Y | I25: Goal statement in English. | J25: Promote industrialisation: 25% processed domestically by 2027
A26: Structure | B26: goals | C26: text_km | D26: text | F26: N | I26: Goal statement in Khmer.
A27: Structure | B27: goals | C27: sort_order | D27: integer | F27: Y | I27: Display order. | J27: 2
A28: Structure | B28: clusters | C28: policy_id | D28: uuid | E28: FK | F28: Y | G28: policies.id | I28: Policy. | J28: NCP-2022
A29: Structure | B29: clusters | C29: goal_id | D29: uuid | E29: FK | F29: Y | G29: goals.id | H29: Goal in the same policy | I29: Goal the cluster delivers. | J29: G2
A30: Structure | B30: clusters | C30: code | D30: text | E30: UK | F30: Y | H30: Unique within the policy | I30: Short code. | J30: processing
A31: Structure | B31: clusters | C31: name_en | D31: text | F31: Y | I31: Name. | J31: Processing
A32: Structure | B32: clusters | C32: name_km | D32: text | F32: N | I32: Name in Khmer.
A33: Structure | B33: clusters | C33: sort_order | D33: integer | F33: Y | I33: Display order. | J33: 2
A34: Structure | B34: ministries | C34: code | D34: text | E34: UK | F34: Y | H34: Lowercase; never change once used (join key across years) | I34: Stable code, same as the Kobo choice name. | J34: maff
A35: Structure | B35: ministries | C35: short_name | D35: text | F35: Y | I35: Abbreviation. | J35: MAFF
A36: Structure | B36: ministries | C36: name_en | D36: text | F36: Y | I36: Full name in English. | J36: Ministry of Agriculture, Forestry and Fisheries
A37: Structure | B37: ministries | C37: name_km | D37: text | F37: N | I37: Full name in Khmer. | J37: ក្រសួងកសិកម្ម រុក្ខាប្រមាញ់ និងនេសាទ
A38: Structure | B38: ministries | C38: type | D38: text | F38: Y | H38: ministry | institution | secretariat | partner | J38: ministry
A39: Structure | B39: ministries | C39: status | D39: text | F39: Y | H39: active | archived | I39: Archive instead of delete. | J39: active
A40: Structure | B40: programmes | C40: policy_id | D40: uuid | E40: FK | F40: Y | G40: policies.id | I40: Owning policy. | J40: NCP-2022
...

Sheet Allowed values
A1: List | B1: Value | C1: Meaning
A2: role | B2: admin | C2: Administrator (M&E manager); may also review
A3: role | B3: reviewer | C3: Reviewer
A4: role | B4: focal | C4: Ministry focal point (own ministry only)
A5: role | B5: viewer | C5: Viewer (Committee): approved figures only
A6: submission state | B6: draft | C6: Being filled; not visible to reviewers
A7: submission state | B7: submitted | C7: Sent to MoC; locked
A8: submission state | B8: in_review | C8: A reviewer is checking it
A9: submission state | B9: returned | C9: Query sent; ministry must correct (new revision)
A10: submission state | B10: approved | C10: Accepted; values become official results
A11: submission state | B11: rejected | C11: Not accepted; kept for the record
A12: submission state | B12: superseded | C12: Replaced by a later approved revision
... A44: cluster | B44: export | C44: Actions 29–44 (Goal 3)

Sheet Rules
A1: Type | B1: Rule | C1: Why
A2: Isolation | B2: Every row (except workspaces) has a workspace_id, and every link stays inside one workspace. | C2: A second policy/customer can never see Cashew data.
A3: Uniqueness | B3: One submission per ministry, reporting year and form. | C3: Matches the manual: submit once per ministry per year.
A4: Uniqueness | B4: One approved result per indicator and reporting year. | C4: Dashboards can never show two competing official values.
A5: Uniqueness | B5: One lead ministry per action; each action indicator has exactly one reporting ministry. | C5: No double counting of joint actions.
A6: Immutability | B6: A submitted revision's answers never change. Corrections create a new revision. | C6: Reviewers can always see what was originally sent.
A7: Immutability | B7: Published form versions and report versions are frozen (checked by hash). | C7: Old reports keep their original numbers after corrections.
A8: Immutability | B8: review_events and audit_events are insert-only; no one can edit or delete them. | C8: A trustworthy trail of decisions.
A9: Versioning | B9: Changing an indicator's meaning, unit or formula creates a new indicator version; results keep the version they used. | C9: Historic results stay interpretable.
A10: Versioning | B10: Target changes create a new target revision with a reason. | C10: Reports reference the target actually used.
A11: Workflow | B11: Nobody approves a revision they entered, including the Administrator. | C11: Owner decision, 26 Sep 2026.
A12: Workflow | B12: Returned and rejected decisions need a reason; approval needs the four verification checks and no open blocking flags. | C12: Manual section 3.1.
... A19: Personal data | B19: Respondent name and phone are visible to the M&E team only and excluded from exports to the Committee. | C19: Minimum personal data.

Sheet Open questions
A1: # | B1: Question | C1: Family | D1: Answer (Secretariat) | E1: Answered by / date
A2: Q1 | B2: One programme per ministry: is this right for all 17 institutions (e.g. NBC, CDC, CMAA)? | C2: Structure
A3: Q2 | B3: Does every action indicator always have exactly one reporting ministry? | C3: Structure
A4: Q3 | B4: Annual reporting only for the pilot, or quarterly for some data (e.g. GDCE exports)? | C4: Indicators
A5: Q4 | B5: Where are evidence files stored: Vercel Blob, Supabase Storage, or left in Kobo with links? | C5: Collection
A6: Q5 | B6: Should respondent name and phone be stored at all, or only the platform user who submitted? | C6: Collection
A7: Q6 | B7: How long are evidence files and submissions kept (retention period)? | C7: Control
A8: Q7 | B8: Should the 2025 data be loaded as approved history, and the 2026 illustrative records left out? | C8: Results
A9: Q8 | B9: Import run table (Kobo sync history) is left for release R2. Agree? | C9: Control
